2025-10-16 10:23:35,485 - ERROR - Pipeline initialization failed: HTTPConnectionPool(host='vault', port=8200): Max retries exceeded with url: /v1/auth/token/lookup-self (Caused by NameResolutionError("<urllib3.connection.HTTPConnection object at 0x00000264D4E52F90>: Failed to resolve 'vault' ([Errno 11001] getaddrinfo failed)"))
Traceback (most recent call last):
  File "C:\Users\tekno asya\Desktop\copilot\forex_env\Lib\site-packages\urllib3\connection.py", line 198, in _new_conn
    sock = connection.create_connection(
        (self._dns_host, self.port),
    ...<2 lines>...
        socket_options=self.socket_options,
    )
  File "C:\Users\tekno asya\Desktop\copilot\forex_env\Lib\site-packages\urllib3\util\connection.py", line 60, in create_connection
    for res in socket.getaddrinfo(host, port, family, socket.SOCK_STREAM):
               ~~~~~~~~~~~~~~~~~~^^^^^^^^^^^^^^^^^^^^^^^^^^^^^^^^^^^^^^^^
  File "C:\Users\Anaconda3\Lib\socket.py", line 977, in getaddrinfo
    for res in _socket.getaddrinfo(host, port, family, type, proto, flags):
               ~~~~~~~~~~~~~~~~~~~^^^^^^^^^^^^^^^^^^^^^^^^^^^^^^^^^^^^^^^^
socket.gaierror: [Errno 11001] getaddrinfo failed

The above exception was the direct cause of the following exception:

Traceback (most recent call last):
  File "C:\Users\tekno asya\Desktop\copilot\forex_env\Lib\site-packages\urllib3\connectionpool.py", line 787, in urlopen
    response = self._make_request(
        conn,
    ...<10 lines>...
        **response_kw,
    )
  File "C:\Users\tekno asya\Desktop\copilot\forex_env\Lib\site-packages\urllib3\connectionpool.py", line 493, in _make_request
    conn.request(
    ~~~~~~~~~~~~^
        method,
        ^^^^^^^
    ...<6 lines>...
        enforce_content_length=enforce_content_length,
        ^^^^^^^^^^^^^^^^^^^^^^^^^^^^^^^^^^^^^^^^^^^^^^
    )
    ^
  File "C:\Users\tekno asya\Desktop\copilot\forex_env\Lib\site-packages\urllib3\connection.py", line 494, in request
    self.endheaders()
    ~~~~~~~~~~~~~~~^^
  File "C:\Users\Anaconda3\Lib\http\client.py", line 1333, in endheaders
    self._send_output(message_body, encode_chunked=encode_chunked)
    ~~~~~~~~~~~~~~~~~^^^^^^^^^^^^^^^^^^^^^^^^^^^^^^^^^^^^^^^^^^^^^
  File "C:\Users\Anaconda3\Lib\http\client.py", line 1093, in _send_output
    self.send(msg)
    ~~~~~~~~~^^^^^
  File "C:\Users\Anaconda3\Lib\http\client.py", line 1037, in send
    self.connect()
    ~~~~~~~~~~~~^^
  File "C:\Users\tekno asya\Desktop\copilot\forex_env\Lib\site-packages\urllib3\connection.py", line 325, in connect
    self.sock = self._new_conn()
                ~~~~~~~~~~~~~~^^
  File "C:\Users\tekno asya\Desktop\copilot\forex_env\Lib\site-packages\urllib3\connection.py", line 205, in _new_conn
    raise NameResolutionError(self.host, self, e) from e
urllib3.exceptions.NameResolutionError: <urllib3.connection.HTTPConnection object at 0x00000264D4E52F90>: Failed to resolve 'vault' ([Errno 11001] getaddrinfo failed)

The above exception was the direct cause of the following exception:

Traceback (most recent call last):
  File "C:\Users\tekno asya\Desktop\copilot\forex_env\Lib\site-packages\requests\adapters.py", line 644, in send
    resp = conn.urlopen(
        method=request.method,
    ...<9 lines>...
        chunked=chunked,
    )
  File "C:\Users\tekno asya\Desktop\copilot\forex_env\Lib\site-packages\urllib3\connectionpool.py", line 841, in urlopen
    retries = retries.increment(
        method, url, error=new_e, _pool=self, _stacktrace=sys.exc_info()[2]
    )
  File "C:\Users\tekno asya\Desktop\copilot\forex_env\Lib\site-packages\urllib3\util\retry.py", line 519, in increment
    raise MaxRetryError(_pool, url, reason) from reason  # type: ignore[arg-type]
    ^^^^^^^^^^^^^^^^^^^^^^^^^^^^^^^^^^^^^^^^^^^^^^^^^^^
urllib3.exceptions.MaxRetryError: HTTPConnectionPool(host='vault', port=8200): Max retries exceeded with url: /v1/auth/token/lookup-self (Caused by NameResolutionError("<urllib3.connection.HTTPConnection object at 0x00000264D4E52F90>: Failed to resolve 'vault' ([Errno 11001] getaddrinfo failed)"))

During handling of the above exception, another exception occurred:

Traceback (most recent call last):
  File "c:\Users\tekno asya\Desktop\copilot\run_live.py", line 313, in <module>
    pipeline = Pipeline(config_manager, data_provider)
  File "c:\Users\tekno asya\Desktop\copilot\run_live.py", line 47, in __init__
    self.vault = VaultSecretsManager(vault_url, vault_token)
                 ~~~~~~~~~~~~~~~~~~~^^^^^^^^^^^^^^^^^^^^^^^^
  File "c:\Users\tekno asya\Desktop\copilot\modules\vault_manager.py", line 13, in __init__
    if not self.client.is_authenticated():
           ~~~~~~~~~~~~~~~~~~~~~~~~~~~~^^
  File "C:\Users\tekno asya\Desktop\copilot\forex_env\Lib\site-packages\hvac\v1\__init__.py", line 512, in is_authenticated
    self.lookup_token()
    ~~~~~~~~~~~~~~~~~^^
  File "C:\Users\tekno asya\Desktop\copilot\forex_env\Lib\site-packages\hvac\v1\__init__.py", line 433, in lookup_token
    return self._adapter.get(path, wrap_ttl=wrap_ttl)
           ~~~~~~~~~~~~~~~~~^^^^^^^^^^^^^^^^^^^^^^^^^
  File "C:\Users\tekno asya\Desktop\copilot\forex_env\Lib\site-packages\hvac\adapters.py", line 146, in get
    return self.request("get", url, **kwargs)
           ~~~~~~~~~~~~^^^^^^^^^^^^^^^^^^^^^^
  File "C:\Users\tekno asya\Desktop\copilot\forex_env\Lib\site-packages\hvac\adapters.py", line 408, in request
    response = super().request(*args, **kwargs)
  File "C:\Users\tekno asya\Desktop\copilot\forex_env\Lib\site-packages\hvac\adapters.py", line 367, in request
    response = self.session.request(
        method=method,
    ...<3 lines>...
        **_kwargs
    )
  File "C:\Users\tekno asya\Desktop\copilot\forex_env\Lib\site-packages\requests\sessions.py", line 589, in request
    resp = self.send(prep, **send_kwargs)
  File "C:\Users\tekno asya\Desktop\copilot\forex_env\Lib\site-packages\requests\sessions.py", line 703, in send
    r = adapter.send(request, **kwargs)
  File "C:\Users\tekno asya\Desktop\copilot\forex_env\Lib\site-packages\requests\adapters.py", line 677, in send
    raise ConnectionError(e, request=request)
requests.exceptions.ConnectionError: HTTPConnectionPool(host='vault', port=8200): Max retries exceeded with url: /v1/auth/token/lookup-self (Caused by NameResolutionError("<urllib3.connection.HTTPConnection object at 0x00000264D4E52F90>: Failed to resolve 'vault' ([Errno 11001] getaddrinfo failed)"))
2025-10-16 18:59:16,236 - ERROR - Pipeline startup failed: HTTPConnectionPool(host='vault', port=8200): Max retries exceeded with url: /v1/auth/token/lookup-self (Caused by NameResolutionError("<urllib3.connection.HTTPConnection object at 0x000001B538B6DBD0>: Failed to resolve 'vault' ([Errno 11001] getaddrinfo failed)"))
Traceback (most recent call last):
  File "C:\Users\tekno asya\Desktop\copilot\forex_env\Lib\site-packages\urllib3\connection.py", line 198, in _new_conn
    sock = connection.create_connection(
        (self._dns_host, self.port),
    ...<2 lines>...
        socket_options=self.socket_options,
    )
  File "C:\Users\tekno asya\Desktop\copilot\forex_env\Lib\site-packages\urllib3\util\connection.py", line 60, in create_connection
    for res in socket.getaddrinfo(host, port, family, socket.SOCK_STREAM):
               ~~~~~~~~~~~~~~~~~~^^^^^^^^^^^^^^^^^^^^^^^^^^^^^^^^^^^^^^^^
  File "C:\Users\Anaconda3\Lib\socket.py", line 977, in getaddrinfo
    for res in _socket.getaddrinfo(host, port, family, type, proto, flags):
               ~~~~~~~~~~~~~~~~~~~^^^^^^^^^^^^^^^^^^^^^^^^^^^^^^^^^^^^^^^^
socket.gaierror: [Errno 11001] getaddrinfo failed

The above exception was the direct cause of the following exception:

Traceback (most recent call last):
  File "C:\Users\tekno asya\Desktop\copilot\forex_env\Lib\site-packages\urllib3\connectionpool.py", line 787, in urlopen
    response = self._make_request(
        conn,
    ...<10 lines>...
        **response_kw,
    )
  File "C:\Users\tekno asya\Desktop\copilot\forex_env\Lib\site-packages\urllib3\connectionpool.py", line 493, in _make_request
    conn.request(
    ~~~~~~~~~~~~^
        method,
        ^^^^^^^
    ...<6 lines>...
        enforce_content_length=enforce_content_length,
        ^^^^^^^^^^^^^^^^^^^^^^^^^^^^^^^^^^^^^^^^^^^^^^
    )
    ^
  File "C:\Users\tekno asya\Desktop\copilot\forex_env\Lib\site-packages\urllib3\connection.py", line 494, in request
    self.endheaders()
    ~~~~~~~~~~~~~~~^^
  File "C:\Users\Anaconda3\Lib\http\client.py", line 1333, in endheaders
    self._send_output(message_body, encode_chunked=encode_chunked)
    ~~~~~~~~~~~~~~~~~^^^^^^^^^^^^^^^^^^^^^^^^^^^^^^^^^^^^^^^^^^^^^
  File "C:\Users\Anaconda3\Lib\http\client.py", line 1093, in _send_output
    self.send(msg)
    ~~~~~~~~~^^^^^
  File "C:\Users\Anaconda3\Lib\http\client.py", line 1037, in send
    self.connect()
    ~~~~~~~~~~~~^^
  File "C:\Users\tekno asya\Desktop\copilot\forex_env\Lib\site-packages\urllib3\connection.py", line 325, in connect
    self.sock = self._new_conn()
                ~~~~~~~~~~~~~~^^
  File "C:\Users\tekno asya\Desktop\copilot\forex_env\Lib\site-packages\urllib3\connection.py", line 205, in _new_conn
    raise NameResolutionError(self.host, self, e) from e
urllib3.exceptions.NameResolutionError: <urllib3.connection.HTTPConnection object at 0x000001B538B6DBD0>: Failed to resolve 'vault' ([Errno 11001] getaddrinfo failed)

The above exception was the direct cause of the following exception:

Traceback (most recent call last):
  File "C:\Users\tekno asya\Desktop\copilot\forex_env\Lib\site-packages\requests\adapters.py", line 644, in send
    resp = conn.urlopen(
        method=request.method,
    ...<9 lines>...
        chunked=chunked,
    )
  File "C:\Users\tekno asya\Desktop\copilot\forex_env\Lib\site-packages\urllib3\connectionpool.py", line 841, in urlopen
    retries = retries.increment(
        method, url, error=new_e, _pool=self, _stacktrace=sys.exc_info()[2]
    )
  File "C:\Users\tekno asya\Desktop\copilot\forex_env\Lib\site-packages\urllib3\util\retry.py", line 519, in increment
    raise MaxRetryError(_pool, url, reason) from reason  # type: ignore[arg-type]
    ^^^^^^^^^^^^^^^^^^^^^^^^^^^^^^^^^^^^^^^^^^^^^^^^^^^
urllib3.exceptions.MaxRetryError: HTTPConnectionPool(host='vault', port=8200): Max retries exceeded with url: /v1/auth/token/lookup-self (Caused by NameResolutionError("<urllib3.connection.HTTPConnection object at 0x000001B538B6DBD0>: Failed to resolve 'vault' ([Errno 11001] getaddrinfo failed)"))

During handling of the above exception, another exception occurred:

Traceback (most recent call last):
  File "c:\Users\tekno asya\Desktop\copilot\run_live.py", line 349, in <module>
    pipeline = Pipeline(config_manager, data_provider)
  File "c:\Users\tekno asya\Desktop\copilot\run_live.py", line 53, in __init__
    self.vault = VaultSecretsManager(vault_url, vault_token)
                 ~~~~~~~~~~~~~~~~~~~^^^^^^^^^^^^^^^^^^^^^^^^
  File "c:\Users\tekno asya\Desktop\copilot\modules\vault_manager.py", line 13, in __init__
    if not self.client.is_authenticated():
           ~~~~~~~~~~~~~~~~~~~~~~~~~~~~^^
  File "C:\Users\tekno asya\Desktop\copilot\forex_env\Lib\site-packages\hvac\v1\__init__.py", line 512, in is_authenticated
    self.lookup_token()
    ~~~~~~~~~~~~~~~~~^^
  File "C:\Users\tekno asya\Desktop\copilot\forex_env\Lib\site-packages\hvac\v1\__init__.py", line 433, in lookup_token
    return self._adapter.get(path, wrap_ttl=wrap_ttl)
           ~~~~~~~~~~~~~~~~~^^^^^^^^^^^^^^^^^^^^^^^^^
  File "C:\Users\tekno asya\Desktop\copilot\forex_env\Lib\site-packages\hvac\adapters.py", line 146, in get
    return self.request("get", url, **kwargs)
           ~~~~~~~~~~~~^^^^^^^^^^^^^^^^^^^^^^
  File "C:\Users\tekno asya\Desktop\copilot\forex_env\Lib\site-packages\hvac\adapters.py", line 408, in request
    response = super().request(*args, **kwargs)
  File "C:\Users\tekno asya\Desktop\copilot\forex_env\Lib\site-packages\hvac\adapters.py", line 367, in request
    response = self.session.request(
        method=method,
    ...<3 lines>...
        **_kwargs
    )
  File "C:\Users\tekno asya\Desktop\copilot\forex_env\Lib\site-packages\requests\sessions.py", line 589, in request
    resp = self.send(prep, **send_kwargs)
  File "C:\Users\tekno asya\Desktop\copilot\forex_env\Lib\site-packages\requests\sessions.py", line 703, in send
    r = adapter.send(request, **kwargs)
  File "C:\Users\tekno asya\Desktop\copilot\forex_env\Lib\site-packages\requests\adapters.py", line 677, in send
    raise ConnectionError(e, request=request)
requests.exceptions.ConnectionError: HTTPConnectionPool(host='vault', port=8200): Max retries exceeded with url: /v1/auth/token/lookup-self (Caused by NameResolutionError("<urllib3.connection.HTTPConnection object at 0x000001B538B6DBD0>: Failed to resolve 'vault' ([Errno 11001] getaddrinfo failed)"))
2025-10-16 19:03:15,404 - ERROR - Pipeline startup failed: HTTPConnectionPool(host='vault', port=8201): Max retries exceeded with url: /v1/auth/token/lookup-self (Caused by NameResolutionError("<urllib3.connection.HTTPConnection object at 0x0000021D4D94DBD0>: Failed to resolve 'vault' ([Errno 11001] getaddrinfo failed)"))
Traceback (most recent call last):
  File "C:\Users\tekno asya\Desktop\copilot\forex_env\Lib\site-packages\urllib3\connection.py", line 198, in _new_conn
    sock = connection.create_connection(
        (self._dns_host, self.port),
    ...<2 lines>...
        socket_options=self.socket_options,
    )
  File "C:\Users\tekno asya\Desktop\copilot\forex_env\Lib\site-packages\urllib3\util\connection.py", line 60, in create_connection
    for res in socket.getaddrinfo(host, port, family, socket.SOCK_STREAM):
               ~~~~~~~~~~~~~~~~~~^^^^^^^^^^^^^^^^^^^^^^^^^^^^^^^^^^^^^^^^
  File "C:\Users\Anaconda3\Lib\socket.py", line 977, in getaddrinfo
    for res in _socket.getaddrinfo(host, port, family, type, proto, flags):
               ~~~~~~~~~~~~~~~~~~~^^^^^^^^^^^^^^^^^^^^^^^^^^^^^^^^^^^^^^^^
socket.gaierror: [Errno 11001] getaddrinfo failed

The above exception was the direct cause of the following exception:

Traceback (most recent call last):
  File "C:\Users\tekno asya\Desktop\copilot\forex_env\Lib\site-packages\urllib3\connectionpool.py", line 787, in urlopen
    response = self._make_request(
        conn,
    ...<10 lines>...
        **response_kw,
    )
  File "C:\Users\tekno asya\Desktop\copilot\forex_env\Lib\site-packages\urllib3\connectionpool.py", line 493, in _make_request
    conn.request(
    ~~~~~~~~~~~~^
        method,
        ^^^^^^^
    ...<6 lines>...
        enforce_content_length=enforce_content_length,
        ^^^^^^^^^^^^^^^^^^^^^^^^^^^^^^^^^^^^^^^^^^^^^^
    )
    ^
  File "C:\Users\tekno asya\Desktop\copilot\forex_env\Lib\site-packages\urllib3\connection.py", line 494, in request
    self.endheaders()
    ~~~~~~~~~~~~~~~^^
  File "C:\Users\Anaconda3\Lib\http\client.py", line 1333, in endheaders
    self._send_output(message_body, encode_chunked=encode_chunked)
    ~~~~~~~~~~~~~~~~~^^^^^^^^^^^^^^^^^^^^^^^^^^^^^^^^^^^^^^^^^^^^^
  File "C:\Users\Anaconda3\Lib\http\client.py", line 1093, in _send_output
    self.send(msg)
    ~~~~~~~~~^^^^^
  File "C:\Users\Anaconda3\Lib\http\client.py", line 1037, in send
    self.connect()
    ~~~~~~~~~~~~^^
  File "C:\Users\tekno asya\Desktop\copilot\forex_env\Lib\site-packages\urllib3\connection.py", line 325, in connect
    self.sock = self._new_conn()
                ~~~~~~~~~~~~~~^^
  File "C:\Users\tekno asya\Desktop\copilot\forex_env\Lib\site-packages\urllib3\connection.py", line 205, in _new_conn
    raise NameResolutionError(self.host, self, e) from e
urllib3.exceptions.NameResolutionError: <urllib3.connection.HTTPConnection object at 0x0000021D4D94DBD0>: Failed to resolve 'vault' ([Errno 11001] getaddrinfo failed)

The above exception was the direct cause of the following exception:

Traceback (most recent call last):
  File "C:\Users\tekno asya\Desktop\copilot\forex_env\Lib\site-packages\requests\adapters.py", line 644, in send
    resp = conn.urlopen(
        method=request.method,
    ...<9 lines>...
        chunked=chunked,
    )
  File "C:\Users\tekno asya\Desktop\copilot\forex_env\Lib\site-packages\urllib3\connectionpool.py", line 841, in urlopen
    retries = retries.increment(
        method, url, error=new_e, _pool=self, _stacktrace=sys.exc_info()[2]
    )
  File "C:\Users\tekno asya\Desktop\copilot\forex_env\Lib\site-packages\urllib3\util\retry.py", line 519, in increment
    raise MaxRetryError(_pool, url, reason) from reason  # type: ignore[arg-type]
    ^^^^^^^^^^^^^^^^^^^^^^^^^^^^^^^^^^^^^^^^^^^^^^^^^^^
urllib3.exceptions.MaxRetryError: HTTPConnectionPool(host='vault', port=8201): Max retries exceeded with url: /v1/auth/token/lookup-self (Caused by NameResolutionError("<urllib3.connection.HTTPConnection object at 0x0000021D4D94DBD0>: Failed to resolve 'vault' ([Errno 11001] getaddrinfo failed)"))

During handling of the above exception, another exception occurred:

Traceback (most recent call last):
  File "c:\Users\tekno asya\Desktop\copilot\run_live.py", line 349, in <module>
    pipeline = Pipeline(config_manager, data_provider)
  File "c:\Users\tekno asya\Desktop\copilot\run_live.py", line 53, in __init__
    self.vault = VaultSecretsManager(vault_url, vault_token)
                 ~~~~~~~~~~~~~~~~~~~^^^^^^^^^^^^^^^^^^^^^^^^
  File "c:\Users\tekno asya\Desktop\copilot\modules\vault_manager.py", line 13, in __init__
    if not self.client.is_authenticated():
           ~~~~~~~~~~~~~~~~~~~~~~~~~~~~^^
  File "C:\Users\tekno asya\Desktop\copilot\forex_env\Lib\site-packages\hvac\v1\__init__.py", line 512, in is_authenticated
    self.lookup_token()
    ~~~~~~~~~~~~~~~~~^^
  File "C:\Users\tekno asya\Desktop\copilot\forex_env\Lib\site-packages\hvac\v1\__init__.py", line 433, in lookup_token
    return self._adapter.get(path, wrap_ttl=wrap_ttl)
           ~~~~~~~~~~~~~~~~~^^^^^^^^^^^^^^^^^^^^^^^^^
  File "C:\Users\tekno asya\Desktop\copilot\forex_env\Lib\site-packages\hvac\adapters.py", line 146, in get
    return self.request("get", url, **kwargs)
           ~~~~~~~~~~~~^^^^^^^^^^^^^^^^^^^^^^
  File "C:\Users\tekno asya\Desktop\copilot\forex_env\Lib\site-packages\hvac\adapters.py", line 408, in request
    response = super().request(*args, **kwargs)
  File "C:\Users\tekno asya\Desktop\copilot\forex_env\Lib\site-packages\hvac\adapters.py", line 367, in request
    response = self.session.request(
        method=method,
    ...<3 lines>...
        **_kwargs
    )
  File "C:\Users\tekno asya\Desktop\copilot\forex_env\Lib\site-packages\requests\sessions.py", line 589, in request
    resp = self.send(prep, **send_kwargs)
  File "C:\Users\tekno asya\Desktop\copilot\forex_env\Lib\site-packages\requests\sessions.py", line 703, in send
    r = adapter.send(request, **kwargs)
  File "C:\Users\tekno asya\Desktop\copilot\forex_env\Lib\site-packages\requests\adapters.py", line 677, in send
    raise ConnectionError(e, request=request)
requests.exceptions.ConnectionError: HTTPConnectionPool(host='vault', port=8201): Max retries exceeded with url: /v1/auth/token/lookup-self (Caused by NameResolutionError("<urllib3.connection.HTTPConnection object at 0x0000021D4D94DBD0>: Failed to resolve 'vault' ([Errno 11001] getaddrinfo failed)"))
2025-10-16 19:46:51 W. Central Africa Standard Time - INFO - Initializing Vault client with URL: http://vault:8201
2025-10-16 21:03:52 W. Central Africa Standard Time - INFO - Initializing Vault client with URL: http://vault:8201
2025-10-16 21:04:08 W. Central Africa Standard Time - WARNING - Vault connection attempt 1/4 failed: HTTPConnectionPool(host='vault', port=8201): Max retries exceeded with url: /v1/auth/token/lookup-self (Caused by NameResolutionError("<urllib3.connection.HTTPConnection object at 0x0000027C6C1F5810>: Failed to resolve 'vault' ([Errno 11001] getaddrinfo failed)")). Retrying in 1.0s...
2025-10-16 21:04:25 W. Central Africa Standard Time - WARNING - Vault connection attempt 2/4 failed: HTTPConnectionPool(host='vault', port=8201): Max retries exceeded with url: /v1/auth/token/lookup-self (Caused by NameResolutionError("<urllib3.connection.HTTPConnection object at 0x0000027C6C16F350>: Failed to resolve 'vault' ([Errno 11001] getaddrinfo failed)")). Retrying in 2.0s...
2025-10-16 21:04:43 W. Central Africa Standard Time - WARNING - Vault connection attempt 3/4 failed: HTTPConnectionPool(host='vault', port=8201): Max retries exceeded with url: /v1/auth/token/lookup-self (Caused by NameResolutionError("<urllib3.connection.HTTPConnection object at 0x0000027C6C16FBD0>: Failed to resolve 'vault' ([Errno 11001] getaddrinfo failed)")). Retrying in 4.0s...
2025-10-16 21:05:03 W. Central Africa Standard Time - WARNING - Vault initialization failed after 4 attempts: HTTPConnectionPool(host='vault', port=8201): Max retries exceeded with url: /v1/auth/token/lookup-self (Caused by NameResolutionError("<urllib3.connection.HTTPConnection object at 0x0000027C6C260490>: Failed to resolve 'vault' ([Errno 11001] getaddrinfo failed)")). Proceeding without Vault secrets.
2025-10-16 21:05:03 W. Central Africa Standard Time - WARNING - No Vault client available, cannot fetch telegram
2025-10-16 21:37:04 W. Central Africa Standard Time - INFO - Initializing Vault client with URL: http://vault:8201
2025-10-16 21:37:19 W. Central Africa Standard Time - WARNING - Vault connection attempt 1/4 failed: HTTPConnectionPool(host='vault', port=8201): Max retries exceeded with url: /v1/auth/token/lookup-self (Caused by NameResolutionError("<urllib3.connection.HTTPConnection object at 0x0000026CC99C5940>: Failed to resolve 'vault' ([Errno 11001] getaddrinfo failed)")). Retrying in 1.0s...
2025-10-16 21:37:36 W. Central Africa Standard Time - WARNING - Vault connection attempt 2/4 failed: HTTPConnectionPool(host='vault', port=8201): Max retries exceeded with url: /v1/auth/token/lookup-self (Caused by NameResolutionError("<urllib3.connection.HTTPConnection object at 0x0000026CC9A39590>: Failed to resolve 'vault' ([Errno 11001] getaddrinfo failed)")). Retrying in 2.0s...
2025-10-16 21:37:54 W. Central Africa Standard Time - WARNING - Vault connection attempt 3/4 failed: HTTPConnectionPool(host='vault', port=8201): Max retries exceeded with url: /v1/auth/token/lookup-self (Caused by NameResolutionError("<urllib3.connection.HTTPConnection object at 0x0000026CC9A39E10>: Failed to resolve 'vault' ([Errno 11001] getaddrinfo failed)")). Retrying in 4.0s...
2025-10-16 21:38:14 W. Central Africa Standard Time - WARNING - Vault initialization failed after 4 attempts: HTTPConnectionPool(host='vault', port=8201): Max retries exceeded with url: /v1/auth/token/lookup-self (Caused by NameResolutionError("<urllib3.connection.HTTPConnection object at 0x0000026CC9A3A690>: Failed to resolve 'vault' ([Errno 11001] getaddrinfo failed)")). Proceeding without Vault secrets.
2025-10-16 21:38:14 W. Central Africa Standard Time - WARNING - No Vault client available, cannot fetch telegram
2025-10-16 21:38:15 W. Central Africa Standard Time - INFO - Initializing Vault client with URL: http://vault:8201
2025-10-16 21:38:30 W. Central Africa Standard Time - WARNING - Vault connection attempt 1/4 failed: HTTPConnectionPool(host='vault', port=8201): Max retries exceeded with url: /v1/auth/token/lookup-self (Caused by NameResolutionError("<urllib3.connection.HTTPConnection object at 0x0000026CC9A3B020>: Failed to resolve 'vault' ([Errno 11001] getaddrinfo failed)")). Retrying in 1.0s...
2025-10-16 21:38:47 W. Central Africa Standard Time - WARNING - Vault connection attempt 2/4 failed: HTTPConnectionPool(host='vault', port=8201): Max retries exceeded with url: /v1/auth/token/lookup-self (Caused by NameResolutionError("<urllib3.connection.HTTPConnection object at 0x0000026CC9A3A360>: Failed to resolve 'vault' ([Errno 11001] getaddrinfo failed)")). Retrying in 2.0s...
2025-10-16 21:39:05 W. Central Africa Standard Time - WARNING - Vault connection attempt 3/4 failed: HTTPConnectionPool(host='vault', port=8201): Max retries exceeded with url: /v1/auth/token/lookup-self (Caused by NameResolutionError("<urllib3.connection.HTTPConnection object at 0x0000026CC9A38F30>: Failed to resolve 'vault' ([Errno 11001] getaddrinfo failed)")). Retrying in 4.0s...
2025-10-16 21:39:25 W. Central Africa Standard Time - WARNING - Vault initialization failed after 4 attempts: HTTPConnectionPool(host='vault', port=8201): Max retries exceeded with url: /v1/auth/token/lookup-self (Caused by NameResolutionError("<urllib3.connection.HTTPConnection object at 0x0000026CC9A39150>: Failed to resolve 'vault' ([Errno 11001] getaddrinfo failed)")). Proceeding without Vault secrets.
2025-10-16 21:39:25 W. Central Africa Standard Time - WARNING - No Vault client available, cannot fetch telegram
2025-10-18 10:12:28 W. Central Africa Standard Time - INFO - Initializing Vault client with URL: http://127.0.0.1:8200
2025-10-18 10:12:28 W. Central Africa Standard Time - ERROR - Vault authentication failed
2025-10-18 10:12:28 W. Central Africa Standard Time - WARNING - Vault connection attempt 1/4 failed: Invalid Vault token or unreachable server. Retrying in 1.0s...
2025-10-18 10:12:29 W. Central Africa Standard Time - ERROR - Vault authentication failed
2025-10-18 10:12:29 W. Central Africa Standard Time - WARNING - Vault connection attempt 2/4 failed: Invalid Vault token or unreachable server. Retrying in 2.0s...
2025-10-18 10:12:31 W. Central Africa Standard Time - ERROR - Vault authentication failed
2025-10-18 10:12:31 W. Central Africa Standard Time - WARNING - Vault connection attempt 3/4 failed: Invalid Vault token or unreachable server. Retrying in 4.0s...
2025-10-18 10:12:35 W. Central Africa Standard Time - ERROR - Vault authentication failed
2025-10-18 10:12:35 W. Central Africa Standard Time - WARNING - Vault initialization failed after 4 attempts: Invalid Vault token or unreachable server. Proceeding without Vault secrets.
2025-10-18 10:12:40 W. Central Africa Standard Time - INFO - Initializing Vault client with URL: http://127.0.0.1:8200
2025-10-18 10:12:40 W. Central Africa Standard Time - ERROR - Vault authentication failed
2025-10-18 10:12:40 W. Central Africa Standard Time - WARNING - Vault connection attempt 1/4 failed: Invalid Vault token or unreachable server. Retrying in 1.0s...
2025-10-18 10:12:41 W. Central Africa Standard Time - ERROR - Vault authentication failed
2025-10-18 10:12:41 W. Central Africa Standard Time - WARNING - Vault connection attempt 2/4 failed: Invalid Vault token or unreachable server. Retrying in 2.0s...
2025-10-18 10:12:43 W. Central Africa Standard Time - ERROR - Vault authentication failed
2025-10-18 10:12:43 W. Central Africa Standard Time - WARNING - Vault connection attempt 3/4 failed: Invalid Vault token or unreachable server. Retrying in 4.0s...
2025-10-18 10:12:47 W. Central Africa Standard Time - ERROR - Vault authentication failed
2025-10-18 10:12:47 W. Central Africa Standard Time - WARNING - Vault initialization failed after 4 attempts: Invalid Vault token or unreachable server. Proceeding without Vault secrets.
2025-10-18 10:12:47 W. Central Africa Standard Time - WARNING - No Vault client available, cannot fetch telegram
2025-10-18 11:38:56 W. Central Africa Standard Time - INFO - Initializing Vault client with URL: http://127.0.0.1:8200
2025-10-18 11:38:56 W. Central Africa Standard Time - ERROR - Vault authentication failed
2025-10-18 11:38:56 W. Central Africa Standard Time - WARNING - Vault connection attempt 1/4 failed: Invalid Vault token or unreachable server. Retrying in 1.0s...
2025-10-18 11:38:57 W. Central Africa Standard Time - ERROR - Vault authentication failed
2025-10-18 11:38:57 W. Central Africa Standard Time - WARNING - Vault connection attempt 2/4 failed: Invalid Vault token or unreachable server. Retrying in 2.0s...
2025-10-18 11:38:59 W. Central Africa Standard Time - ERROR - Vault authentication failed
2025-10-18 11:38:59 W. Central Africa Standard Time - WARNING - Vault connection attempt 3/4 failed: Invalid Vault token or unreachable server. Retrying in 4.0s...
2025-10-18 11:39:03 W. Central Africa Standard Time - ERROR - Vault authentication failed
2025-10-18 11:39:03 W. Central Africa Standard Time - WARNING - Vault initialization failed after 4 attempts: Invalid Vault token or unreachable server. Proceeding without Vault secrets.
2025-10-18 11:39:08 W. Central Africa Standard Time - INFO - Initializing Vault client with URL: http://127.0.0.1:8200
2025-10-18 11:39:08 W. Central Africa Standard Time - ERROR - Vault authentication failed
2025-10-18 11:39:08 W. Central Africa Standard Time - WARNING - Vault connection attempt 1/4 failed: Invalid Vault token or unreachable server. Retrying in 1.0s...
2025-10-18 11:39:09 W. Central Africa Standard Time - ERROR - Vault authentication failed
2025-10-18 11:39:09 W. Central Africa Standard Time - WARNING - Vault connection attempt 2/4 failed: Invalid Vault token or unreachable server. Retrying in 2.0s...
2025-10-18 11:39:11 W. Central Africa Standard Time - ERROR - Vault authentication failed
2025-10-18 11:39:11 W. Central Africa Standard Time - WARNING - Vault connection attempt 3/4 failed: Invalid Vault token or unreachable server. Retrying in 4.0s...
2025-10-18 11:39:15 W. Central Africa Standard Time - ERROR - Vault authentication failed
2025-10-18 11:39:15 W. Central Africa Standard Time - WARNING - Vault initialization failed after 4 attempts: Invalid Vault token or unreachable server. Proceeding without Vault secrets.
2025-10-18 11:39:15 W. Central Africa Standard Time - WARNING - No Vault client available, cannot fetch telegram
2025-10-18 12:06:23 W. Central Africa Standard Time - INFO - Initializing Vault client with URL: http://127.0.0.1:8200
2025-10-18 12:06:24 W. Central Africa Standard Time - INFO - Vault client authenticated successfully
2025-10-18 12:06:29 W. Central Africa Standard Time - INFO - Initializing Vault client with URL: http://127.0.0.1:8200
2025-10-18 12:06:29 W. Central Africa Standard Time - INFO - Vault client authenticated successfully
2025-10-18 12:06:29 W. Central Africa Standard Time - INFO - Retrieved API keys for telegram
2025-10-18 14:07:12 W. Central Africa Standard Time - INFO - Initializing Vault client with URL: http://127.0.0.1:8200
2025-10-18 14:07:12 W. Central Africa Standard Time - INFO - Vault client authenticated successfully
